Workbook

Sheet README
B2: Attendance & Fines Tracker — Project Guide
B4: This workbook tracks member attendance and fines across the quarter, then analyzes the data for attendance trends, outstanding fines, and gender-based segmentation.
B6: Sheet | C6: Purpose | D6: Start here if you want to...
B7: Attendance key | C7: Defines the P / L / E / U codes used across the workbook, plus fine-status labels. | D7: Understand what a code means
B8: Quarter 2 26.27 | C8: Cleaned wide-format version with status, fine amounts, and unexcused-absence counts calculated per member. | D8: Check a member’s fine total or status
B9: Data Cleaning | C9: Cleaned wide-format version with status, fine amounts, and unexcused-absence counts calculated per member. | D9: Check a member’s fine total or status
B10: Main Table | C10: Long/unpivoted version of the data (one row per member per meeting date). Feeds the pivot tables and charts. | D10: Build a new pivot table or chart
B11: Attendance Analysis | C11: Per-member attendance rate breakdown (P/L/E/U), meeting-day-level attendance stats, and outlier detection (Mean/Median/Mode/Std Dev, flagged when a member’s rate deviates from the mean by more than 1.5× the standard deviation). | D11: See who is attending irregularly
B12: Fines Analysis | C12: Outstanding vs. paid fines, fine amounts by absence type, and a Top Owing Members ranking. | D12: Chase up unpaid fines
B13: Segmentation Analysis | C13: Cross-tab of gender against unexcused absences and total fines. | D13: Check for patterns by gender
B16: Note: pivot tables in this workbook recalculate automatically when opened in Excel (Formulas > Calculation Options > Automatic, the default). If a table looks out of date, right-click it and choose Refresh, or Data > Refresh All.

Sheet Attendance key
B1: SETTINGS
B2: ATTENDANCE KEY
B3: Change the attendance key by updating the values below.
B4: Add classes by duplicating the 'Class 1' sheet tab. New tabs will reference this same attendance key.
B6: ATTENDANCE KEY
B7: P | C7: Present
B8: L | C8: Late
B9: E | C9: Excused absence
B10: U | C10: Unexcused absence
C11: Reached out to
C12: Paid
C13: Paid half
C14: Issues
C15: Not owing

Sheet Quarter 2 26.27
C1: =IFERROR(CONCATENATE(" Enter ", 'Attendance key'!$B$7, " for ",'Attendance key'!$C$7, ", ", 'Attendance key'!$B$8, " for ", 'Attendance key'!$C$8, ", ", 'Attendance key'!$B$9, " for ", 'Attendance key'!$C$9, ", and ", 'Attendance key'!$B$10, " for ", 'Attendance key'!$C$10, ". Use the 'Attendance key' tab to customize. "),"") -> Enter P for Present, L for Late, E for Excused absence, and U for Unexcused absence. Use the 'Attendance key' tab to customize.
B2: Members | C2: 46145 | D2: =C2+7 -> 46152 | E2: =D2+7 -> 46159 | F2: =E2+7 -> 46166 | G2: 46173 | H2: =G2+7 -> 46180 | I2: =H2+7 -> 46187 | J2: =I2+7 -> 46194 | K2: =J2+7 -> 46201 | L2: =K2+7 -> 46208 | M2: =L2+7 -> 46215 | N2: 46222 | O2: 46229 | S2: Status | T2: ='Attendance key'!$C8 -> Late | U2: ='Attendance key'!$C9 -> Excused absence | V2: ='Attendance key'!$C10 -> Unexcused absence
C3: Sun | D3: Sun | E3: Sun | F3: Sun | G3: Sun | H3: Sun. LM | I3: Sun | J3: Sun | K3: Sun | L3: Sun | M3: Sun | N3: Sun | O3: Sun | T3: ='Attendance key'!$B8 -> L | U3: ='Attendance key'!$B9 -> E | V3: ='Attendance key'!$B10 -> U
B4: Zain | C4: P | D4: P | E4: P | F4: P | G4: P | I4: P | J4: P | K4: P | L4: E | M4: P | N4: P | T4: 0 | U4: 0 | V4: 0
B5: Seyii | C5: P | D5: P | E5: P | F5: P | G5: P | I5: P | J5: P | K5: L | L5: U | M5: P | N5: P | T5: 300 | U5: 0 | V5: 500
B6: Tobi | C6: P | D6: U | E6: U | F6: P | G6: P | I6: E | J6: U | K6: P | L6: U | M6: U | N6: P | T6: 0 | U6: 0 | V6: 2500
B7: Bayo | C7: P | D7: P | E7: P | F7: P | G7: P | I7: P | J7: P | K7: P | L7: U | M7: U | N7: E | T7: 0 | U7: 0 | V7: 1000
B8: John | C8: P | D8: P | E8: P | F8: P | G8: P | I8: P | J8: P | K8: U | L8: P | M8: P | N8: U | T8: 0 | U8: 0 | V8: 1000
B9: Eni | C9: P | D9: P | E9: P | F9: P | G9: P | I9: P | J9: P | K9: P | L9: P | M9: P | N9: P | T9: 0 | U9: 0 | V9: 0
B10: Sola | C10: P | D10: P | E10: P | F10: L | G10: E | I10: E | J10: P | K10: P | L10: E | M10: P | N10: P | T10: 300 | U10: 0 | V10: 0
B11: Kemi | C11: P | D11: P | E11: P | F11: E | G11: P | I11: P | J11: P | K11: P | L11: E | M11: E | N11: P | T11: 0 | U11: 0 | V11: 0
B12: David | C12: P | D12: P | E12: L | F12: L | G12: L | I12: L | J12: P | K12: L | L12: E | M12: P | N12: P | T12: 1500 | U12: 0 | V12: 0
B13: Eli | C13: U | D13: U | E13: P | F13: P | G13: P | I13: E | J13: P | K13: P | L13: P | M13: P | N13: U | T13: 0 | U13: 0 | V13: 1500
B14: Suyi | C14: P | D14: P | E14: P | F14: P | G14: P | I14: P | J14: P | K14: E | L14: P | M14: P | N14: P | T14: 0 | U14: 0 | V14: 0
B15: Phebe | C15: L | D15: P | E15: P | F15: L | G15: U | I15: L | J15: P | K15: P | L15: P | M15: P | N15: P | T15: 900 | U15: 0
B16: Lanre | C16: P | D16: P | E16: P | F16: P | G16: P | I16: P | J16: L | K16: L | L16: P | M16: P | N16: P | T16: 600 | U16: 0 | V16: 0
B17: Fawaz | C17: P | D17: P | E17: P | F17: P | G17: P | I17: P | J17: P | K17: L | L17: P | M17: P | N17: P | T17: 300 | U17: 0 | V17: 0
B18: Josh | C18: P | D18: L | E18: P | F18: P | G18: U | I18: P | J18: L | K18: U | L18: P | M18: P | N18: P | T18: 600 | U18: 0 | V18: 1000
B19: Daniel | C19: U | D19: U | E19: P | F19: U | G19: U | I19: U | J19: P | K19: U | L19: P | M19: P | N19: E | T19: 0 | U19: 0 | V19: 3000
B20: Ife | C20: P | D20: P | E20: P | F20: U | G20: L | I20: P | J20: P | K20: P | L20: P | M20: P | N20: L | T20: 600 | U20: 0 | V20: 500
B21: Grace | C21: P | D21: L | E21: U | F21: E | G21: P | I21: P | J21: U | K21: P | L21: U | M21: P | N21: P | T21: 300 | U21: 0 | V21: 1500
B22: Hadassah | C22: P | D22: L | E22: U | F22: E | G22: P | I22: U | J22: P | K22: U | L22: P | M22: P | N22: P | T22: 300 | U22: 0 | V22: 1500
B23: Layo | C23: P | D23: P | E23: P | F23: P | G23: L | I23: P | J23: P | K23: P | L23: P | M23: P | N23: P | T23: 300 | U23: 0 | V23: 0
B24: Fisayo | C24: P | D24: P | E24: P | F24: P | G24: P | I24: P | J24: P | K24: P | L24: P | M24: P | N24: P | T24: 0 | U24: 0 | V24: 0
B25: Tofunmi | C25: P | D25: L | E25: P | F25: P | G25: P | I25: P | J25: P | K25: E | L25: P | M25: U | N25: U | T25: 300 | U25: 0 | V25: 1000
B26: Emma | C26: P | D26: P | E26: U | F26: U | G26: P | I26: P | J26: P | K26: P | L26: P | M26: P | N26: P | T26: 0 | U26: 0 | V26: 1000
B27: Micheal | C27: P | D27: P | E27: P | F27: P | G27: P | I27: L | J27: P | K27: P | L27: P | M27: U | N27: P | T27: 300 | U27: 0 | V27: 500
... B75: Victor | C75: P | D75: P | E75: P | F75: P | G75: P | I75: P | J75: P | K75: P | L75: P | M75: P | N75: U | T75: 0 | U75: 0 | V75: 500
B76: Joel | C76: P | D76: P | E76: P | F76: P | G76: P | I76: P | J76: P | K76: P | M76: U | N76: U | T76: 0 | U76: 0 | V76: 1000

Sheet Data Cleaning
A1: Members | B1: Gender | C1: May 10th | D1: May 17th | E1: May 24th | F1: May 31st | G1: June 7th | H1: June 14th | I1: June 21st | J1: June 28th | K1: July 5th | L1: July 12th | M1: July 19th | N1: Status | O1: Late | P1: Excused Absence | Q1: Unexcused Absence | R1: Amount | S1: Unexcused Absence count | T1: Has Unexcused?
A2: Abisola | B2: F | C2: P | D2: P | E2: U | F2: P | G2: P | H2: P | I2: P | J2: P | K2: P | L2: U | M2: P | N2: Paid | O2: 0 | P2: 0 | Q2: 1000 | R2: =Table4[[#This Row],[Late]]+Table4[[#This Row],[Excused Absence]]+Table4[[#This Row],[Unexcused Absence]] -> 1000 | S2: 2 | T2: No
A3: Adeola | B3: F | C3: P | D3: P | E3: P | F3: P | G3: P | H3: P | I3: P | J3: P | K3: E | L3: P | M3: P | N3: Not owing | O3: 0 | P3: 0 | Q3: 0 | R3: =Table4[[#This Row],[Late]]+Table4[[#This Row],[Excused Absence]]+Table4[[#This Row],[Unexcused Absence]] -> 0 | S3: 0 | T3: Yes
A4: Bayo | B4: M | C4: P | D4: P | E4: P | F4: P | G4: P | H4: P | I4: P | J4: P | K4: U | L4: U | M4: E | N4: Reached out to | O4: 0 | P4: 0 | Q4: 1000 | R4: =Table4[[#This Row],[Late]]+Table4[[#This Row],[Excused Absence]]+Table4[[#This Row],[Unexcused Absence]] -> 1000 | S4: 2 | T4: No
A5: Daniel | B5: M | C5: U | D5: E | E5: U | F5: U | G5: P | H5: P | I5: P | J5: P | K5: P | L5: L | M5: U | N5: Reached out to | O5: 300 | P5: 0 | Q5: 2000 | R5: =Table4[[#This Row],[Late]]+Table4[[#This Row],[Excused Absence]]+Table4[[#This Row],[Unexcused Absence]] -> 2300 | S5: 4 | T5: No
A6: Dariel | B6: M | C6: U | D6: U | E6: P | F6: U | G6: U | H6: U | I6: P | J6: U | K6: P | L6: P | M6: E | N6: Reached out to | O6: 0 | P6: 0 | Q6: 3000 | R6: =Table4[[#This Row],[Late]]+Table4[[#This Row],[Excused Absence]]+Table4[[#This Row],[Unexcused Absence]] -> 3000 | S6: 6 | T6: No
A7: David | B7: M | C7: P | D7: P | E7: L | F7: L | G7: L | H7: L | I7: P | J7: L | K7: E | L7: P | M7: P | N7: Reached out to | O7: 1500 | P7: 0 | Q7: 0 | R7: =Table4[[#This Row],[Late]]+Table4[[#This Row],[Excused Absence]]+Table4[[#This Row],[Unexcused Absence]] -> 1500 | S7: 0 | T7: Yes
A8: Deborah | B8: F | C8: P | D8: P | E8: P | F8: P | G8: E | H8: P | I8: P | J8: P | K8: P | L8: P | M8: P | N8: Not owing | O8: 0 | P8: 0 | Q8: 0 | R8: =Table4[[#This Row],[Late]]+Table4[[#This Row],[Excused Absence]]+Table4[[#This Row],[Unexcused Absence]] -> 0 | S8: 0 | T8: Yes
A9: Dunamis | B9: F | C9: P | D9: P | E9: P | F9: P | G9: U | H9: P | I9: P | J9: U | K9: P | L9: P | M9: P | N9: Paid | O9: 0 | P9: 0 | Q9: 1000 | R9: =Table4[[#This Row],[Late]]+Table4[[#This Row],[Excused Absence]]+Table4[[#This Row],[Unexcused Absence]] -> 1000 | S9: 2 | T9: No
A10: Ebuka | B10: M | C10: P | D10: P | E10: P | F10: P | G10: P | H10: P | I10: P | J10: P | K10: P | L10: P | M10: P | N10: Not owing | O10: 0 | P10: 0 | Q10: 0 | R10: =Table4[[#This Row],[Late]]+Table4[[#This Row],[Excused Absence]]+Table4[[#This Row],[Unexcused Absence]] -> 0 | S10: 0 | T10: Yes
A11: Eli | B11: M | C11: U | D11: U | E11: P | F11: P | G11: P | H11: E | I11: P | J11: P | K11: P | L11: P | M11: U | N11: Reached out to | O11: 0 | P11: 0 | Q11: 1500 | R11: =Table4[[#This Row],[Late]]+Table4[[#This Row],[Excused Absence]]+Table4[[#This Row],[Unexcused Absence]] -> 1500 | S11: 3 | T11: No
A12: Ella | B12: F | C12: P | D12: P | E12: P | F12: P | G12: P | H12: P | I12: P | J12: P | K12: P | L12: P | M12: P | N12: Not owing | O12: 0 | P12: 0 | Q12: 0 | R12: =Table4[[#This Row],[Late]]+Table4[[#This Row],[Excused Absence]]+Table4[[#This Row],[Unexcused Absence]] -> 0 | S12: 0 | T12: Yes
A13: Emma | B13: M | C13: P | D13: U | E13: P | F13: P | G13: P | H13: L | I13: P | J13: U | K13: P | L13: P | M13: L | N13: Paid | O13: 600 | P13: 0 | Q13: 500 | R13: =Table4[[#This Row],[Late]]+Table4[[#This Row],[Excused Absence]]+Table4[[#This Row],[Unexcused Absence]] -> 1100 | S13: 1 | T13: No
... A29: Israel | B29: M | C29: U | D29: U | E29: P | F29: P | G29: P | H29: U | I29: P | J29: P | K29: U | L29: P | M29: P | N29: Paid | O29: 0 | P29: 0 | Q29: 2000 | R29: =Table4[[#This Row],[Late]]+Table4[[#This Row],[Excused Absence]]+Table4[[#This Row],[Unexcused Absence]] -> 2000 | S29: 4 | T29: No
A30: Joel | B30: M | C30: P | D30: P | E30: P | F30: P | G30: P | H30: P | I30: P | J30: P | L30: U | M30: U | N30: Reached out to | O30: 0 | P30: 0 | Q30: 1000 | R30: =Table4[[#This Row],[Late]]+Table4[[#This Row],[Excused Absence]]+Table4[[#This Row],[Unexcused Absence]] -> 1000 | S30: 2 | T30: No
A31: John | B31: M | C31: P | D31: P | E31: P | F31: P | G31: P | H31: P | I31: P | J31: U | K31: P | L31: P | M31: U | N31: Reached out to | O31: 0 | P31: 0 | Q31: 1000 | R31: =Table4[[#This Row],[Late]]+Table4[[#This Row],[Excused Absence]]+Table4[[#This Row],[Unexcused Absence]] -> 1000 | S31: 2 | T31: No
A32: Johnson | B32: M | C32: P | D32: P | E32: U | F32: P | G32: P | H32: E | I32: P | J32: P | K32: P | L32: U | M32: U | N32: Paid | O32: 0 | P32: 0 | Q32: 1500 | R32: =Table4[[#This Row],[Late]]+Table4[[#This Row],[Excused Absence]]+Table4[[#This Row],[Unexcused Absence]] -> 1500 | S32: 3 | T32: No
A33: Josephine | B33: F | C33: L | D33: U | E33: P | F33: P | G33: P | H33: U | I33: P | J33: P | K33: U | L33: P | M33: E | N33: Reached out to | O33: 300 | P33: 0 | Q33: 1500 | R33: =Table4[[#This Row],[Late]]+Table4[[#This Row],[Excused Absence]]+Table4[[#This Row],[Unexcused Absence]] -> 1800 | S33: 3 | T33: No
A34: Josh | B34: M | C34: P | D34: L | E34: P | F34: P | G34: U | H34: P | I34: L | J34: U | K34: P | L34: P | M34: P | N34: Reached out to | O34: 600 | P34: 0 | Q34: 1000 | R34: =Table4[[#This Row],[Late]]+Table4[[#This Row],[Excused Absence]]+Table4[[#This Row],[Unexcused Absence]] -> 1600 | S34: 2 | T34: No
A35: Joy | B35: F | C35: P | D35: P | E35: P | F35: P | G35: P | H35: E | I35: U | J35: P | K35: P | L35: P | M35: P | N35: Paid | O35: 0 | P35: 0 | Q35: 500 | R35: =Table4[[#This Row],[Late]]+Table4[[#This Row],[Excused Absence]]+Table4[[#This Row],[Unexcused Absence]] -> 500 | S35: 1 | T35: No
A36: Kamal | B36: M | C36: P | D36: P | E36: P | F36: U | G36: P | H36: P | I36: P | J36: U | K36: P | L36: P | M36: P | N36: Paid | O36: 0 | P36: 0 | Q36: 1000 | R36: =Table4[[#This Row],[Late]]+Table4[[#This Row],[Excused Absence]]+Table4[[#This Row],[Unexcused Absence]] -> 1000 | S36: 2 | T36: No
A37: Kemi | B37: F | C37: P | D37: P | E37: P | F37: E | G37: P | H37: P | I37: P | J37: P | K37: E | L37: E | M37: P | N37: Not owing | O37: 0 | P37: 0 | Q37: 0 | R37: =Table4[[#This Row],[Late]]+Table4[[#This Row],[Excused Absence]]+Table4[[#This Row],[Unexcused Absence]] -> 0 | S37: 0 | T37: Yes
A38: Kenny | B38: F | C38: P | D38: L | E38: P | F38: U | G38: U | H38: L | I38: P | J38: P | K38: P | L38: P | M38: P | N38: Paid | O38: 600 | P38: 0 | Q38: 1000 | R38: =Table4[[#This Row],[Late]]+Table4[[#This Row],[Excused Absence]]+Table4[[#This Row],[Unexcused Absence]] -> 1600 | S38: 2 | T38: No
A39: Kiekie | B39: F | C39: P | D39: P | E39: P | F39: P | G39: P | H39: E | I39: P | J39: P | K39: P | L39: P | M39: P | N39: Not owing | O39: 0 | P39: 0 | Q39: 0 | R39: =Table4[[#This Row],[Late]]+Table4[[#This Row],[Excused Absence]]+Table4[[#This Row],[Unexcused Absence]] -> 0 | S39: 0 | T39: Yes
A40: Lanre | B40: M | C40: P | D40: P | E40: P | F40: P | G40: P | H40: P | I40: L | J40: L | K40: P | L40: P | M40: P | N40: Reached out to | O40: 600 | P40: 0 | Q40: 0 | R40: =Table4[[#This Row],[Late]]+Table4[[#This Row],[Excused Absence]]+Table4[[#This Row],[Unexcused Absence]] -> 600 | S40: 0 | T40: Yes
A41: Layo | B41: F | C41: P | D41: P | E41: P | F41: P | G41: L | H41: P | I41: P | J41: P | K41: P | L41: P | M41: P | N41: Reached out to | O41: 300 | P41: 0 | Q41: 0 | R41: =Table4[[#This Row],[Late]]+Table4[[#This Row],[Excused Absence]]+Table4[[#This Row],[Unexcused Absence]] -> 300 | S41: 0 | T41: Yes
A42: Lore | B42: M | C42: P | D42: P | E42: U | F42: P | G42: P | H42: E | I42: P | J42: P | K42: L | L42: E | M42: P | N42: Reached out to | O42: 300 | P42: 0 | Q42: 500 | R42: =Table4[[#This Row],[Late]]+Table4[[#This Row],[Excused Absence]]+Table4[[#This Row],[Unexcused Absence]] -> 800 | S42: 1 | T42: No
... A74: Zain | B74: F | C74: P | D74: P | E74: P | F74: P | G74: P | H74: P | I74: P | J74: P | K74: E | L74: P | M74: P | N74: Not owing | O74: 0 | P74: 0 | Q74: 0 | R74: =Table4[[#This Row],[Late]]+Table4[[#This Row],[Excused Absence]]+Table4[[#This Row],[Unexcused Absence]] -> 0 | S74: 0 | T74: Yes

Sheet Main Table from power query
A1: Members | B1: Gender | C1: Status | D1: Late | E1: Excused Absence | F1: Unexcused Absence | G1: Attribute | H1: Value
A2: Abisola | B2: F | C2: Paid | D2: 0 | E2: 0 | F2: 1000 | G2: May 10th | H2: P
A3: Abisola | B3: F | C3: Paid | D3: 0 | E3: 0 | F3: 1000 | G3: May 17th | H3: P
A4: Abisola | B4: F | C4: Paid | D4: 0 | E4: 0 | F4: 1000 | G4: May 24th | H4: U
A5: Abisola | B5: F | C5: Paid | D5: 0 | E5: 0 | F5: 1000 | G5: May 31st | H5: P
A6: Abisola | B6: F | C6: Paid | D6: 0 | E6: 0 | F6: 1000 | G6: June 7th | H6: P
A7: Abisola | B7: F | C7: Paid | D7: 0 | E7: 0 | F7: 1000 | G7: June 14th | H7: P
A8: Abisola | B8: F | C8: Paid | D8: 0 | E8: 0 | F8: 1000 | G8: June 21st | H8: P
A9: Abisola | B9: F | C9: Paid | D9: 0 | E9: 0 | F9: 1000 | G9: June 28th | H9: P
A10: Abisola | B10: F | C10: Paid | D10: 0 | E10: 0 | F10: 1000 | G10: July 5th | H10: P
A11: Abisola | B11: F | C11: Paid | D11: 0 | E11: 0 | F11: 1000 | G11: July 12th | H11: U
A12: Abisola | B12: F | C12: Paid | D12: 0 | E12: 0 | F12: 1000 | G12: July 19th | H12: P
A13: Abisola | B13: F | C13: Paid | D13: 0 | E13: 0 | F13: 1000 | G13: Amount | H13: 1000
A14: Abisola | B14: F | C14: Paid | D14: 0 | E14: 0 | F14: 1000 | G14: Unexcused Absence count | H14: 2
A15: Abisola | B15: F | C15: Paid | D15: 0 | E15: 0 | F15: 1000 | G15: Has Unexcused? | H15: No
A16: Adeola | B16: F | C16: Not owing | D16: 0 | E16: 0 | F16: 0 | G16: May 10th | H16: P
A17: Adeola | B17: F | C17: Not owing | D17: 0 | E17: 0 | F17: 0 | G17: May 17th | H17: P
A18: Adeola | B18: F | C18: Not owing | D18: 0 | E18: 0 | F18: 0 | G18: May 24th | H18: P
A19: Adeola | B19: F | C19: Not owing | D19: 0 | E19: 0 | F19: 0 | G19: May 31st | H19: P
A20: Adeola | B20: F | C20: Not owing | D20: 0 | E20: 0 | F20: 0 | G20: June 7th | H20: P
A21: Adeola | B21: F | C21: Not owing | D21: 0 | E21: 0 | F21: 0 | G21: June 14th | H21: P
A22: Adeola | B22: F | C22: Not owing | D22: 0 | E22: 0 | F22: 0 | G22: June 21st | H22: P
A23: Adeola | B23: F | C23: Not owing | D23: 0 | E23: 0 | F23: 0 | G23: June 28th | H23: P
A24: Adeola | B24: F | C24: Not owing | D24: 0 | E24: 0 | F24: 0 | G24: July 5th | H24: E
A25: Adeola | B25: F | C25: Not owing | D25: 0 | E25: 0 | F25: 0 | G25: July 12th | H25: P
A26: Adeola | B26: F | C26: Not owing | D26: 0 | E26: 0 | F26: 0 | G26: July 19th | H26: P
A27: Adeola | B27: F | C27: Not owing | D27: 0 | E27: 0 | F27: 0 | G27: Amount | H27: 0
A28: Adeola | B28: F | C28: Not owing | D28: 0 | E28: 0 | F28: 0 | G28: Unexcused Absence count | H28: 0
A29: Adeola | B29: F | C29: Not owing | D29: 0 | E29: 0 | F29: 0 | G29: Has Unexcused? | H29: Yes
A30: Bayo | B30: M | C30: Reached out to | D30: 0 | E30: 0 | F30: 1000 | G30: May 10th | H30: P
A31: Bayo | B31: M | C31: Reached out to | D31: 0 | E31: 0 | F31: 1000 | G31: May 17th | H31: P
A32: Bayo | B32: M | C32: Reached out to | D32: 0 | E32: 0 | F32: 1000 | G32: May 24th | H32: P
A33: Bayo | B33: M | C33: Reached out to | D33: 0 | E33: 0 | F33: 1000 | G33: May 31st | H33: P
A34: Bayo | B34: M | C34: Reached out to | D34: 0 | E34: 0 | F34: 1000 | G34: June 7th | H34: P
A35: Bayo | B35: M | C35: Reached out to | D35: 0 | E35: 0 | F35: 1000 | G35: June 14th | H35: P
A36: Bayo | B36: M | C36: Reached out to | D36: 0 | E36: 0 | F36: 1000 | G36: June 21st | H36: P
A37: Bayo | B37: M | C37: Reached out to | D37: 0 | E37: 0 | F37: 1000 | G37: June 28th | H37: P
A38: Bayo | B38: M | C38: Reached out to | D38: 0 | E38: 0 | F38: 1000 | G38: July 5th | H38: U
A39: Bayo | B39: M | C39: Reached out to | D39: 0 | E39: 0 | F39: 1000 | G39: July 12th | H39: U
A40: Bayo | B40: M | C40: Reached out to | D40: 0 | E40: 0 | F40: 1000 | G40: July 19th | H40: E
...

Sheet Attendance Analysis
A1: Gender | B1: (All)
A3: Count of Value | B3: Attendance
A4: Members | B4: E | C4: L | D4: P | E4: U | F4: Grand Total | I4: Count of Value | J4: Attendance | P4: Attendance statistics | S4: Attendeance rate per members
A5: Abisola | B5: 0 | C5: 0 | D5: 0.81818182 | E5: 0.18181818 | F5: 1 | I5: Meeting days | J5: E | K5: L | L5: P | M5: U | N5: Grand Total | P5: Statistics | Q5: Column1 | R5: Outlier? | S5: Members | T5: Present rate
A6: Adeola | B6: 0.090909091 | C6: 0 | D6: 0.90909091 | E6: 0 | F6: 1 | I6: July 12th | J6: 0.068493151 | K6: 0.02739726 | L6: 0.7260274 | M6: 0.17808219 | N6: 1 | P6: Mean | Q6: =AVERAGE(D5:D77) -> 0.73325031 | R6: =IF(ABS(D5-$Q$6)>1.5*$Q$9,"Yes","No") -> No | S6: Abisola | T6: 0.81818182
A7: Bayo | B7: 0.090909091 | C7: 0 | D7: 0.72727273 | E7: 0.18181818 | F7: 1 | I7: July 19th | J7: 0.054794521 | K7: 0.04109589 | L7: 0.7260274 | M7: 0.17808219 | N7: 1 | P7: Median | Q7: =MEDIAN(D5:D77) -> 0.8 | R7: =IF(ABS(D6-$Q$6)>1.5*$Q$9,"Yes","No") -> No | S7: Adeola | T7: 0.90909091
A8: Daniel | B8: 0.090909091 | C8: 0.090909091 | D8: 0.45454545 | E8: 0.36363636 | F8: 1 | I8: July 5th | J8: 0.083333333 | K8: 0.055555556 | L8: 0.73611111 | M8: 0.125 | N8: 1 | P8: Mode | Q8: =_xlfn.MODE.SNGL(D5:D77) -> 0.90909091 | R8: =IF(ABS(D7-$Q$6)>1.5*$Q$9,"Yes","No") -> No | S8: Bayo | T8: 0.72727273
A9: Dariel | B9: 0.090909091 | C9: 0 | D9: 0.36363636 | E9: 0.54545455 | F9: 1 | I9: June 14th | J9: 0.12328767 | K9: 0.1369863 | L9: 0.65753425 | M9: 0.082191781 | N9: 1 | P9: Standard deviation | Q9: =_xlfn.STDEV.S(D5:D77) -> 0.20337047 | R9: =IF(ABS(D8-$Q$6)>1.5*$Q$9,"Yes","No") -> No | S9: Daniel | T9: 0.45454545
A10: David | B10: 0.090909091 | C10: 0.45454545 | D10: 0.45454545 | E10: 0 | F10: 1 | I10: June 21st | J10: 0 | K10: 0.054794521 | L10: 0.84931507 | M10: 0.095890411 | N10: 1 | R10: =IF(ABS(D9-$Q$6)>1.5*$Q$9,"Yes","No") -> Yes | S10: Dariel | T10: 0.36363636
A11: Deborah | B11: 0.090909091 | C11: 0 | D11: 0.90909091 | E11: 0 | F11: 1 | I11: June 28th | J11: 0.054794521 | K11: 0.068493151 | L11: 0.64383562 | M11: 0.23287671 | N11: 1 | R11: =IF(ABS(D10-$Q$6)>1.5*$Q$9,"Yes","No") -> No | S11: David | T11: 0.45454545
A12: Dunamis | B12: 0 | C12: 0 | D12: 0.81818182 | E12: 0.18181818 | F12: 1 | I12: June 7th | J12: 0.04109589 | K12: 0.095890411 | L12: 0.73972603 | M12: 0.12328767 | N12: 1 | R12: =IF(ABS(D11-$Q$6)>1.5*$Q$9,"Yes","No") -> No | S12: Deborah | T12: 0.90909091
A13: Ebuka | B13: 0 | C13: 0 | D13: 1 | E13: 0 | F13: 1 | I13: May 10th | J13: 0 | K13: 0.054794521 | L13: 0.84931507 | M13: 0.095890411 | N13: 1 | R13: =IF(ABS(D12-$Q$6)>1.5*$Q$9,"Yes","No") -> No | S13: Dunamis | T13: 0.81818182
A14: Eli | B14: 0.090909091 | C14: 0 | D14: 0.63636364 | E14: 0.27272727 | F14: 1 | I14: May 17th | J14: 0.01369863 | K14: 0.082191781 | L14: 0.69863014 | M14: 0.20547945 | N14: 1 | R14: =IF(ABS(D13-$Q$6)>1.5*$Q$9,"Yes","No") -> No | S14: Ebuka | T14: 1
A15: Ella | B15: 0 | C15: 0 | D15: 1 | E15: 0 | F15: 1 | I15: May 24th | J15: 0.01369863 | K15: 0.01369863 | L15: 0.73972603 | M15: 0.23287671 | N15: 1 | R15: =IF(ABS(D14-$Q$6)>1.5*$Q$9,"Yes","No") -> No | S15: Eli | T15: 0.63636364
A16: Emma | B16: 0 | C16: 0.18181818 | D16: 0.63636364 | E16: 0.18181818 | F16: 1 | I16: May 31st | J16: 0.054794521 | K16: 0.068493151 | L16: 0.69863014 | M16: 0.17808219 | N16: 1 | R16: =IF(ABS(D15-$Q$6)>1.5*$Q$9,"Yes","No") -> No | S16: Ella | T16: 1
A17: Eni | B17: 0 | C17: 0 | D17: 1 | E17: 0 | F17: 1 | I17: Grand Total | J17: 0.046134663 | K17: 0.063591022 | L17: 0.73316708 | M17: 0.15710723 | N17: 1 | R17: =IF(ABS(D16-$Q$6)>1.5*$Q$9,"Yes","No") -> No | S17: Emma | T17: 0.63636364
A18: Esther | B18: 0 | C18: 0 | D18: 0.81818182 | E18: 0.18181818 | F18: 1 | R18: =IF(ABS(D17-$Q$6)>1.5*$Q$9,"Yes","No") -> No | S18: Eni | T18: 1
A19: Faith | B19: 0 | C19: 0 | D19: 1 | E19: 0 | F19: 1 | R19: =IF(ABS(D18-$Q$6)>1.5*$Q$9,"Yes","No") -> No | S19: Esther | T19: 0.81818182
A20: Fawaz | B20: 0 | C20: 0.090909091 | D20: 0.90909091 | E20: 0 | F20: 1 | R20: =IF(ABS(D19-$Q$6)>1.5*$Q$9,"Yes","No") -> No | S20: Faith | T20: 1
A21: Feranmi | B21: 0 | C21: 0 | D21: 1 | E21: 0 | F21: 1 | R21: =IF(ABS(D20-$Q$6)>1.5*$Q$9,"Yes","No") -> No | S21: Fawaz | T21: 0.90909091
A22: Fisayo | B22: 0 | C22: 0 | D22: 1 | E22: 0 | F22: 1 | R22: =IF(ABS(D21-$Q$6)>1.5*$Q$9,"Yes","No") -> No | S22: Feranmi | T22: 1
A23: Funmi | B23: 0.090909091 | C23: 0.36363636 | D23: 0.27272727 | E23: 0.27272727 | F23: 1 | R23: =IF(ABS(D22-$Q$6)>1.5*$Q$9,"Yes","No") -> No | S23: Fisayo | T23: 1
A24: Grace | B24: 0.090909091 | C24: 0.090909091 | D24: 0.54545455 | E24: 0.27272727 | F24: 1 | R24: =IF(ABS(D23-$Q$6)>1.5*$Q$9,"Yes","No") -> Yes | S24: Funmi | T24: 0.27272727
A25: Great | B25: 0 | C25: 0 | D25: 1 | E25: 0 | F25: 1 | R25: =IF(ABS(D24-$Q$6)>1.5*$Q$9,"Yes","No") -> No | S25: Grace | T25: 0.54545455
A26: Hadassah | B26: 0.090909091 | C26: 0.090909091 | D26: 0.54545455 | E26: 0.27272727 | F26: 1 | R26: =IF(ABS(D25-$Q$6)>1.5*$Q$9,"Yes","No") -> No | S26: Great | T26: 1
A27: Haddy | B27: 0 | C27: 0 | D27: 0.90909091 | E27: 0.090909091 | F27: 1 | R27: =IF(ABS(D26-$Q$6)>1.5*$Q$9,"Yes","No") -> No | S27: Hadassah | T27: 0.54545455
A28: Hikmah | B28: 0 | C28: 0 | D28: 1 | E28: 0 | F28: 1 | R28: =IF(ABS(D27-$Q$6)>1.5*$Q$9,"Yes","No") -> No | S28: Haddy | T28: 0.90909091
A29: Idowu | B29: 0 | C29: 0 | D29: 0.90909091 | E29: 0.090909091 | F29: 1 | R29: =IF(ABS(D28-$Q$6)>1.5*$Q$9,"Yes","No") -> No | S29: Hikmah | T29: 1
... A78: Grand Total | B78: 0.046134663 | C78: 0.063591022 | D78: 0.73316708 | E78: 0.15710723 | F78: 1 | R78: =IF(ABS(D77-$Q$6)>1.5*$Q$9,"Yes","No") -> No | S78: Zain | T78: 0.90909091
S79: Grand Total | T79: 0.73316708

Sheet Fines Analysis
A1: Gender | B1: F | G1: Gender | H1: (All)
B2: Outstanding fines vs paid fines | G2: Status | H2: Reached out to | I2: Top Owing Members
A3: Fine Status | B3: Members count | C3: Late amount | D3: Excused Absence amount | E3: Unexcused absence amount
A4: Not owing | B4: 12 | C4: 0 | D4: 0 | E4: 0 | G4: Row Labels | H4: Sum of Late | I4: Sum of Unexcused Absence
A5: Paid | B5: 13 | C5: 2700 | D5: 0 | E5: 12000 | G5: David | H5: 1500 | I5: 0
A6: Reached out to | B6: 10 | C6: 3600 | D6: 0 | E6: 10000 | G6: Funmi | H6: 1200 | I6: 1500
A7: Grand Total | B7: 35 | C7: 6300 | D7: 0 | E7: 22000 | G7: Phebe | H7: 900 | I7: 500
G8: Tayo | H8: 600 | I8: 500
G9: Lanre | H9: 600 | I9: 0
G10: Raheem | H10: 600 | I10: 4000
G11: Sam | H11: 600 | I11: 500
G12: Ife | H12: 600 | I12: 500
G13: Tomi | H13: 600 | I13: 1500
G14: Josh | H14: 600 | I14: 1000
G15: Marvelous | H15: 600 | I15: 2000
G16: Seyii | H16: 300 | I16: 500
G17: Josephine | H17: 300 | I17: 1500
G18: Theo | H18: 300 | I18: 500
G19: Layo | H19: 300 | I19: 0
... G39: Grand Total | H39: 11700 | I39: 38500

Sheet Segmentation Analysis
A1: Gender | B1: (All)
A3: Members | B3: Total Fine | C3: Unexcused Absences | E3: Gender | F3: No | G3: Yes
A4: Abisola | B4: 1000 | C4: 2 | E4: Male | F4: =($H$10*F12)/$H12 -> 24.931507 | G4: =($H$10*G12)/$H12 -> 10.068493
A5: Adeola | B5: 0 | C5: 0 | E5: Female | F5: =($H$11*F12)/$H12 -> 27.068493 | G5: =($H$11*G12)/$H12 -> 10.931507
A6: Bayo | B6: 1000 | C6: 2
A7: Daniel | B7: 2300 | C7: 4
A8: Dariel | B8: 3000 | C8: 6 | E8: Number of members | F8: Unexcused absences?
A9: David | B9: 1500 | C9: 0 | E9: Gender | F9: No | G9: Yes | H9: Grand Total
A10: Deborah | B10: 0 | C10: 0 | E10: F | F10: 21 | G10: 14 | H10: 35
A11: Dunamis | B11: 1000 | C11: 2 | E11: M | F11: 31 | G11: 7 | H11: 38
A12: Ebuka | B12: 0 | C12: 0 | E12: Grand Total | F12: 52 | G12: 21 | H12: 73
A13: Eli | B13: 1500 | C13: 3
A14: Ella | B14: 0 | C14: 0 | E14: Chi Square test - is unexcused absence associated with gender?
A15: Emma | B15: 1100 | C15: 1 | E15: P-value | F15: =_xlfn.CHISQ.TEST(F10:G11,F4:G5) -> 0.041878331
A16: Eni | B16: 0 | C16: 0 | E16: Since p-value is less than 0.05, gender and unexcused absence have no relationship
A17: Esther | B17: 1000 | C17: 2
A18: Faith | B18: 0 | C18: 0
A19: Fawaz | B19: 300 | C19: 0
A20: Feranmi | B20: 0 | C20: 0
A21: Fisayo | B21: 0 | C21: 0
A22: Funmi | B22: 2700 | C22: 3
A23: Grace | B23: 1800 | C23: 3
A24: Great | B24: 0 | C24: 0
A25: Hadassah | B25: 1800 | C25: 3
A26: Haddy | B26: 500 | C26: 1
A27: Hikmah | B27: 0 | C27: 0
A28: Idowu | B28: 500 | C28: 1
... A77: Grand Total | B77: 77100 | C77: 123

Sheet Data visualization
